2025-10-04 17:20:15,645 - INFO - Starting enterprise-grade training pipeline...
2025-10-04 17:20:15,646 - INFO - Loading data from processed_data.pkl
2025-10-04 17:20:15,646 - ERROR - Failed to load pickle: [Errno 2] No such file or directory: 'processed_data.pkl'
2025-10-04 17:20:15,646 - ERROR - Training failed: [Errno 2] No such file or directory: 'processed_data.pkl'
Traceback (most recent call last):
  File "/home/onlyahad/Desktop/Recommendation System/main_files/recommendation_system.py", line 110, in load_and_validate_data
    with open(pickle_path, 'rb') as f:
         ^^^^^^^^^^^^^^^^^^^^^^^
FileNotFoundError: [Errno 2] No such file or directory: 'processed_data.pkl'

During handling of the above exception, another exception occurred:

Traceback (most recent call last):
  File "/home/onlyahad/Desktop/Recommendation System/main_files/recommendation_system.py", line 1368, in <module>
    main()
  File "/home/onlyahad/Desktop/Recommendation System/main_files/recommendation_system.py", line 1356, in main
    model, history = trainer.train(args.pickle_path)
                     ^^^^^^^^^^^^^^^^^^^^^^^^^^^^^^^
  File "/home/onlyahad/Desktop/Recommendation System/main_files/recommendation_system.py", line 894, in train
    data = self.data_processor.load_and_validate_data(pickle_path)
           ^^^^^^^^^^^^^^^^^^^^^^^^^^^^^^^^^^^^^^^^^^^^^^^^^^^^^^^
  File "/home/onlyahad/Desktop/Recommendation System/main_files/recommendation_system.py", line 114, in load_and_validate_data
    data = pd.read_pickle(pickle_path)
           ^^^^^^^^^^^^^^^^^^^^^^^^^^^
  File "/home/onlyahad/miniconda3/envs/ml_global/lib/python3.11/site-packages/pandas/io/pickle.py", line 185, in read_pickle
    with get_handle(
         ^^^^^^^^^^^
  File "/home/onlyahad/miniconda3/envs/ml_global/lib/python3.11/site-packages/pandas/io/common.py", line 882, in get_handle
    handle = open(handle, ioargs.mode)
             ^^^^^^^^^^^^^^^^^^^^^^^^^
FileNotFoundError: [Errno 2] No such file or directory: 'processed_data.pkl'
